<?xml version="1.0" ?>
<robot xmlns:xacro="http://www.ros.org/wiki/xacro" name="RobotV2">

  <joint name="RobotV2__link_0_JOINT_5" type="revolute">
    <parent link="RobotV2__link_0"/>
    <child link="RobotV2__link_1"/>
    <origin rpy="1.57 0 0" xyz="0.93284  0.85362  0.06166"/>
    <axis xyz="0 0 1"/>
    <limit effort="1000" lower="-1.79769e+308" upper="1.79769e+308" velocity="1000"/>
  </joint>
  <joint name="RobotV2__link_0_JOINT_7" type="revolute">
    <parent link="RobotV2__link_0"/>
    <child link="RobotV2__link_1_clone"/>
    <origin rpy="1.57 0 0" xyz="0.93284 -0.17784  0.06167"/>
    <axis xyz="0 0 1"/>
    <limit effort="1000" lower="-1.79769e+308" upper="1.79769e+308" velocity="1000"/>
  </joint>
  <link name="RobotV2__link_0">
    <inertial>
      <mass value="0.718514"/>
      <origin rpy="0  0  0" xyz="0   0   0.4"/>
      <inertia ixx="0.0488765" ixy="0" ixz="0" iyy="0.24281" iyz="0" izz="0.264198"/>
    </inertial>
    <collision name="RobotV2__collision">
      <origin rpy="0  0  0" xyz="0.25487  0.33038  0.12222"/>
      <geometry>
        <box size="1.95593 0.765993 0.479111"/>
      </geometry>
    </collision>
    <visual name="RobotV2__visual">
      <origin rpy="0  0  0" xyz="0.25487  0.33038  0.12222"/>
      <geometry>
        <box size="1.95593 0.765993 0.479111"/>
      </geometry>
    </visual>

    </link>


  <link name="RobotV2__link_1">
    <inertial>
      <mass value="1"/>
      <origin rpy="0  0  0" xyz="0  0  0"/>
      <inertia ixx="0.145833" ixy="0" ixz="0" iyy="0.145833" iyz="0" izz="0.125"/>
    </inertial>
    <collision name="RobotV2__collision">
      <origin rpy="0  0  0" xyz="0  0  0"/>
      <geometry>
        <cylinder length="0.25" radius="0.3"/>
      </geometry>
    </collision>
    <visual name="RobotV2__visual">
      <origin rpy="0  0  0" xyz="0  0  0"/>
      <geometry>
        <cylinder length="0.25" radius="0.3"/>
      </geometry>
    </visual>
  </link>
  <link name="RobotV2__link_1_clone">
    <inertial>
      <mass value="1"/>
      <origin rpy="0  0  0" xyz="0  0  0"/>
      <inertia ixx="0.145833" ixy="0" ixz="0" iyy="0.145833" iyz="0" izz="0.125"/>
    </inertial>
    <collision name="RobotV2__collision">
      <origin rpy="0  0  0" xyz="0  0  0"/>
      <geometry>
        <cylinder length="0.25" radius="0.3"/>
      </geometry>
    </collision>
    <visual name="RobotV2__visual">
      <origin rpy="0  0  0" xyz="0  0  0"/>
      <geometry>
        <cylinder length="0.25" radius="0.3"/>
      </geometry>
    </visual>
  </link>

  <joint name="camera_joint" type="fixed">
    <axis xyz="0 1 0" />
    <origin xyz="-0.6 0.33 0.38" rpy="0 0 3.14"/>
    <parent link="RobotV2__link_0"/>
    <child link="camera_link"/>
  </joint>

  <!-- Camera -->
  <link name="camera_link">
    <collision>
      <origin xyz="0 0 0" rpy="0 0 0"/>
      <geometry>
    <box size="0.05 0.05 0.05"/>
      </geometry>
    </collision>

    <visual>
      <origin xyz="0 0 0" rpy="0 0 0"/>
      <geometry>
    <box size="0.05 0.05 0.05"/>
      </geometry>
      <material name="red"/>
    </visual>

    <inertial>
      <mass value="1e-5" />
      <origin xyz="0 0 0" rpy="0 0 0"/>
      <inertia ixx="1e-6" ixy="0" ixz="0" iyy="1e-6" iyz="0" izz="1e-6" />
    </inertial>
  </link>

<!-- camera -->
  <gazebo reference="camera_link">
    <sensor type="camera" name="camera1">
      <update_rate>30.0</update_rate>
      <camera name="head">
        <horizontal_fov>1.3962634</horizontal_fov>
        <image>
          <width>800</width>
          <height>800</height>
          <format>R8G8B8</format>
        </image>
        <clip>
          <near>0.02</near>
          <far>300</far>
        </clip>
        <noise>
          <type>gaussian</type>
          <!-- Noise is sampled independently per pixel on each frame.
               That pixel's noise value is added to each of its color
               channels, which at that point lie in the range [0,1]. -->
          <mean>0.0</mean>
          <stddev>0.007</stddev>
        </noise>
      </camera>
      <plugin name="camera_controller" filename="libgazebo_ros_camera.so">
        <alwaysOn>true</alwaysOn>
        <updateRate>0.0</updateRate>
        <cameraName>monrobot/camera1</cameraName>
        <imageTopicName>image_raw</imageTopicName>
        <cameraInfoTopicName>camera_info</cameraInfoTopicName>
        <frameName>camera_link</frameName>
        <hackBaseline>0.07</hackBaseline>
        <distortionK1>0.0</distortionK1>
        <distortionK2>0.0</distortionK2>
        <distortionK3>0.0</distortionK3>
        <distortionT1>0.0</distortionT1>
        <distortionT2>0.0</distortionT2>
      </plugin>
    </sensor>
  </gazebo>

  <transmission name="left_wheel_transmission">
    <type>transmission_interface/SimpleTransmission</type>
    <joint name="RobotV2__link_0_JOINT_5">
      <hardwareInterface>hardware_interface/VelocityJointInterface</hardwareInterface>  
    </joint>
    <actuator name="left_wheel_actuator">
      <mechanicalReduction>7</mechanicalReduction>
      <hardwareInterface>VelocityJointInterface</hardwareInterface>
    </actuator>
  </transmission>

  <transmission name="right_wheel_transmission">
    <type>transmission_interface/SimpleTransmission</type>
    <joint name="RobotV2__link_0_JOINT_7">
      <hardwareInterface>hardware_interface/VelocityJointInterface</hardwareInterface>  
    </joint>
    <actuator name="right_wheel_actuator">
      <mechanicalReduction>7</mechanicalReduction>
      <hardwareInterface>VelocityJointInterface</hardwareInterface>
    </actuator>
  </transmission>

<!-- LIDAR -->
  <xacro:include filename="$(find icpr_robotsimu_results)/model/spinning_joint.urdf.xacro" />

<!-- hokuyo -->
  <gazebo reference="laser_link">
    <sensor type="ray" name="head_hokuyo_sensor">
      <pose>0 0 0 0 0 0</pose>
      <visualize>true</visualize>
      <update_rate>40</update_rate>
      <ray>
        <scan>
          <horizontal>
            <samples>720</samples>
            <resolution>1</resolution>
            <min_angle>-1.570796</min_angle>
            <max_angle>1.570796</max_angle>
          </horizontal>
        </scan>
        <range>
          <min>0.10</min>
          <max>30.0</max>
          <resolution>0.01</resolution>
        </range>
        <noise>
          <type>gaussian</type>
          <!-- Noise parameters based on published spec for Hokuyo laser
               achieving "+-30mm" accuracy at range < 10m.  A mean of 0.0m and
               stddev of 0.01m will put 99.7% of samples within 0.03m of the true
               reading. -->
          <mean>0.0</mean>
          <stddev>0.01</stddev>
        </noise>
      </ray>
      <plugin name="gazebo_ros_head_hokuyo_controller" filename="libgazebo_ros_laser.so">
        <topicName>/monrobot/laser/scan</topicName>
        <frameName>laser_link</frameName>
      </plugin>
    </sensor>
  </gazebo>
</robot>
